<?xml version="1.0" encoding="UTF-8"?>
<testng-results ignored="0" total="4" passed="3" failed="1" skipped="0">
  <reporter-output>
  </reporter-output>
  <suite started-at="2023-06-19T16:04:08Z" name="Suite" finished-at="2023-06-19T16:04:17Z" duration-ms="9226">
    <groups>
    </groups>
    <test started-at="2023-06-19T16:04:08Z" name="Test" finished-at="2023-06-19T16:04:17Z" duration-ms="9226">
      <class name="api.test.UserTests">
        <test-method is-config="true" signature="setupData()[pri:0, instance:api.test.UserTests@42530531]" started-at="2023-06-19T16:04:08Z" name="setupData" finished-at="2023-06-19T16:04:09Z" duration-ms="224" status="PASS">
          <reporter-output>
          </reporter-output>
        </test-method> <!-- setupData -->
        <test-method signature="testPostUser()[pri:1, instance:api.test.UserTests@42530531]" started-at="2023-06-19T16:04:09Z" name="testPostUser" finished-at="2023-06-19T16:04:12Z" duration-ms="3451" status="PASS">
          <reporter-output>
          </reporter-output>
        </test-method> <!-- testPostUser -->
        <test-method signature="getuserdetails()[pri:2, instance:api.test.UserTests@42530531]" started-at="2023-06-19T16:04:12Z" name="getuserdetails" finished-at="2023-06-19T16:04:13Z" duration-ms="1236" status="PASS">
          <reporter-output>
          </reporter-output>
        </test-method> <!-- getuserdetails -->
        <test-method signature="testUpdateUser()[pri:3, instance:api.test.UserTests@42530531]" started-at="2023-06-19T16:04:13Z" name="testUpdateUser" finished-at="2023-06-19T16:04:16Z" duration-ms="2478" status="PASS">
          <reporter-output>
          </reporter-output>
        </test-method> <!-- testUpdateUser -->
        <test-method signature="deleteuserbyusername()[pri:4, instance:api.test.UserTests@42530531]" started-at="2023-06-19T16:04:16Z" name="deleteuserbyusername" finished-at="2023-06-19T16:04:17Z" duration-ms="1432" status="FAIL">
          <exception class="java.lang.AssertionError">
            <message>
              <![CDATA[expected [200] but found [405]]]>
            </message>
            <full-stacktrace>
              <![CDATA[java.lang.AssertionError: expected [200] but found [405]
at org.testng.Assert.fail(Assert.java:96)
at org.testng.Assert.failNotEquals(Assert.java:776)
at org.testng.Assert.assertEqualsImpl(Assert.java:137)
at org.testng.Assert.assertEquals(Assert.java:118)
at org.testng.Assert.assertEquals(Assert.java:652)
at org.testng.Assert.assertEquals(Assert.java:662)
at api.test.UserTests.deleteuserbyusername(UserTests.java:78)
at java.base/jdk.internal.reflect.NativeMethodAccessorImpl.invoke0(Native Method)
at java.base/jdk.internal.reflect.NativeMethodAccessorImpl.invoke(NativeMethodAccessorImpl.java:77)
at java.base/jdk.internal.reflect.DelegatingMethodAccessorImpl.invoke(DelegatingMethodAccessorImpl.java:43)
at java.base/java.lang.reflect.Method.invoke(Method.java:568)
at org.testng.internal.MethodInvocationHelper.invokeMethod(MethodInvocationHelper.java:124)
at org.testng.internal.Invoker.invokeMethod(Invoker.java:583)
at org.testng.internal.Invoker.invokeTestMethod(Invoker.java:719)
at org.testng.internal.Invoker.invokeTestMethods(Invoker.java:989)
at org.testng.internal.TestMethodWorker.invokeTestMethods(TestMethodWorker.java:125)
at org.testng.internal.TestMethodWorker.run(TestMethodWorker.java:109)
at org.testng.TestRunner.privateRun(TestRunner.java:648)
at org.testng.TestRunner.run(TestRunner.java:505)
at org.testng.SuiteRunner.runTest(SuiteRunner.java:455)
at org.testng.SuiteRunner.runSequentially(SuiteRunner.java:450)
at org.testng.SuiteRunner.privateRun(SuiteRunner.java:415)
at org.testng.SuiteRunner.run(SuiteRunner.java:364)
at org.testng.SuiteRunnerWorker.runSuite(SuiteRunnerWorker.java:52)
at org.testng.SuiteRunnerWorker.run(SuiteRunnerWorker.java:84)
at org.testng.TestNG.runSuitesSequentially(TestNG.java:1208)
at org.testng.TestNG.runSuitesLocally(TestNG.java:1137)
at org.testng.TestNG.runSuites(TestNG.java:1049)
at org.testng.TestNG.run(TestNG.java:1017)
at org.testng.remote.AbstractRemoteTestNG.run(AbstractRemoteTestNG.java:115)
at org.testng.remote.RemoteTestNG.initAndRun(RemoteTestNG.java:251)
at org.testng.remote.RemoteTestNG.main(RemoteTestNG.java:77)
]]>
            </full-stacktrace>
          </exception> <!-- java.lang.AssertionError -->
          <reporter-output>
          </reporter-output>
        </test-method> <!-- deleteuserbyusername -->
      </class> <!-- api.test.UserTests -->
    </test> <!-- Test -->
  </suite> <!-- Suite -->
</testng-results>
